package br.com.digitalhouse.Exceptions;

import java.util.ArrayList;

public class Principal {
    public static void main(String[] args) {

//        try {
////            ArrayList<String> lista = new ArrayList<>();
////            lista.add("Jessica");
////            lista.add("João");
////            lista.add("Maria");
////
////            System.out.println(lista.get(3));
////
////        }catch (Exception ex){
////
////            System.out.println("Ocorreu uma exception: "+ex.getMessage());
////            //ex.printStackTrace();
////        }


//        Integer soma = 0;
//
//        try {
//
//            Pessoa pessoa = new Pessoa();
//            pessoa.setRg(1);
//            soma = pessoa.getRg() + 000000;
//            System.out.println(soma);
//
//        } catch (NullPointerException ex) {
//            System.out.println("Deu ruim: " + ex.getCause());
//            ex.printStackTrace();
//
//        }finally {
//            if (soma > 2){
//                System.out.println("A soma é maior que 2");
//            }else{
//                System.out.println("A soma é menor que 2");
//            }
//        }
//
//
//        System.out.println("Aconteceu o print depois do finally pois está no método main");





    }
}
